2019-10-16 13:43:29,718 ERROR: Exception on /upload_progress/ [GET] [in /home/matrizaev/cabinet/venv/lib/python3.6/site-packages/flask/app.py:1891]
Traceback (most recent call last):
  File "/home/matrizaev/cabinet/venv/lib/python3.6/site-packages/flask/app.py", line 2446, in wsgi_app
    response = self.full_dispatch_request()
  File "/home/matrizaev/cabinet/venv/lib/python3.6/site-packages/flask/app.py", line 1951, in full_dispatch_request
    rv = self.handle_user_exception(e)
  File "/home/matrizaev/cabinet/venv/lib/python3.6/site-packages/flask/app.py", line 1820, in handle_user_exception
    reraise(exc_type, exc_value, tb)
  File "/home/matrizaev/cabinet/venv/lib/python3.6/site-packages/flask/_compat.py", line 39, in reraise
    raise value
  File "/home/matrizaev/cabinet/venv/lib/python3.6/site-packages/flask/app.py", line 1949, in full_dispatch_request
    rv = self.dispatch_request()
  File "/home/matrizaev/cabinet/venv/lib/python3.6/site-packages/flask/app.py", line 1935, in dispatch_request
    return self.view_functions[rule.endpoint](**req.view_args)
  File "/home/matrizaev/cabinet/venv/lib/python3.6/site-packages/flask_login/utils.py", line 261, in decorated_view
    return func(*args, **kwargs)
  File "/home/matrizaev/cabinet/app/main/routes.py", line 67, in GetUploadProgress
    return jsonify({'status':job_is_running, 'flash': ['Прогресс обработки товаров: {:.2}%'.format(current_user.GetRQprogress())]})
ValueError: Precision not allowed in integer format specifier
2019-10-16 13:43:30,139 INFO: Cabinet startup [in ./app/__init__.py:73]
2019-10-16 14:14:59,829 INFO: Cabinet startup [in /home/matrizaev/cabinet/app/__init__.py:73]
2019-10-17 17:35:40,672 INFO: Cabinet startup [in /home/matrizaev/cabinet/app/__init__.py:75]
2019-10-18 07:38:37,945 INFO: Cabinet startup [in /home/matrizaev/cabinet/app/__init__.py:75]
2019-10-18 07:44:58,396 INFO: Cabinet startup [in /home/matrizaev/cabinet/app/__init__.py:75]
2019-10-18 07:45:13,232 INFO: Cabinet startup [in /home/matrizaev/cabinet/app/__init__.py:75]
2019-10-18 07:45:33,450 ERROR: Exception on /api/store/1/products [GET] [in /home/matrizaev/cabinet/venv/lib/python3.6/site-packages/flask/app.py:1891]
Traceback (most recent call last):
  File "/home/matrizaev/cabinet/venv/lib/python3.6/site-packages/flask/app.py", line 2446, in wsgi_app
    response = self.full_dispatch_request()
  File "/home/matrizaev/cabinet/venv/lib/python3.6/site-packages/flask/app.py", line 1951, in full_dispatch_request
    rv = self.handle_user_exception(e)
  File "/home/matrizaev/cabinet/venv/lib/python3.6/site-packages/flask/app.py", line 1820, in handle_user_exception
    reraise(exc_type, exc_value, tb)
  File "/home/matrizaev/cabinet/venv/lib/python3.6/site-packages/flask/_compat.py", line 39, in reraise
    raise value
  File "/home/matrizaev/cabinet/venv/lib/python3.6/site-packages/flask/app.py", line 1949, in full_dispatch_request
    rv = self.dispatch_request()
  File "/home/matrizaev/cabinet/venv/lib/python3.6/site-packages/flask/app.py", line 1935, in dispatch_request
    return self.view_functions[rule.endpoint](**req.view_args)
  File "/home/matrizaev/cabinet/venv/lib/python3.6/site-packages/flask_httpauth.py", line 105, in decorated
    return f(*args, **kwargs)
  File "/home/matrizaev/cabinet/app/api/stores.py", line 24, in GetProducts
    data = Product.ToCollectionDict(Product.query.filter(Product.store_id == id), page, per_page, 'api.GetProducts')
NameError: name 'Product' is not defined
2019-10-18 07:45:56,320 INFO: Cabinet startup [in /home/matrizaev/cabinet/app/__init__.py:75]
2019-10-18 07:46:04,536 ERROR: Exception on /api/store/1/products [GET] [in /home/matrizaev/cabinet/venv/lib/python3.6/site-packages/flask/app.py:1891]
Traceback (most recent call last):
  File "/home/matrizaev/cabinet/venv/lib/python3.6/site-packages/flask/app.py", line 2446, in wsgi_app
    response = self.full_dispatch_request()
  File "/home/matrizaev/cabinet/venv/lib/python3.6/site-packages/flask/app.py", line 1951, in full_dispatch_request
    rv = self.handle_user_exception(e)
  File "/home/matrizaev/cabinet/venv/lib/python3.6/site-packages/flask/app.py", line 1820, in handle_user_exception
    reraise(exc_type, exc_value, tb)
  File "/home/matrizaev/cabinet/venv/lib/python3.6/site-packages/flask/_compat.py", line 39, in reraise
    raise value
  File "/home/matrizaev/cabinet/venv/lib/python3.6/site-packages/flask/app.py", line 1949, in full_dispatch_request
    rv = self.dispatch_request()
  File "/home/matrizaev/cabinet/venv/lib/python3.6/site-packages/flask/app.py", line 1935, in dispatch_request
    return self.view_functions[rule.endpoint](**req.view_args)
  File "/home/matrizaev/cabinet/venv/lib/python3.6/site-packages/flask_httpauth.py", line 105, in decorated
    return f(*args, **kwargs)
  File "/home/matrizaev/cabinet/app/api/stores.py", line 24, in GetProducts
    data = Product.ToCollectionDict(Product.query.filter(Product.store_id == id), page, per_page, 'api.GetProducts')
  File "/home/matrizaev/cabinet/app/models.py", line 32, in ToCollectionDict
    **kwargs),
  File "/home/matrizaev/cabinet/venv/lib/python3.6/site-packages/flask/helpers.py", line 370, in url_for
    return appctx.app.handle_url_build_error(error, endpoint, values)
  File "/home/matrizaev/cabinet/venv/lib/python3.6/site-packages/flask/app.py", line 2215, in handle_url_build_error
    reraise(exc_type, exc_value, tb)
  File "/home/matrizaev/cabinet/venv/lib/python3.6/site-packages/flask/_compat.py", line 39, in reraise
    raise value
  File "/home/matrizaev/cabinet/venv/lib/python3.6/site-packages/flask/helpers.py", line 358, in url_for
    endpoint, values, method=method, force_external=external
  File "/home/matrizaev/cabinet/venv/lib/python3.6/site-packages/werkzeug/routing.py", line 2020, in build
    raise BuildError(endpoint, values, method, self)
werkzeug.routing.BuildError: Could not build url for endpoint 'api.GetProducts' with values ['page', 'per_page']. Did you forget to specify values ['id']?
2019-10-18 07:54:34,693 INFO: Cabinet startup [in /home/matrizaev/cabinet/app/__init__.py:75]
2019-10-18 12:44:57,577 INFO: Cabinet startup [in /home/matrizaev/cabinet/app/__init__.py:75]
2019-10-18 12:45:08,516 INFO: Cabinet startup [in /home/matrizaev/cabinet/app/__init__.py:75]
2019-10-18 12:50:17,874 INFO: Cabinet startup [in /home/matrizaev/cabinet/app/__init__.py:75]
2019-10-18 12:50:31,708 INFO: Cabinet startup [in /home/matrizaev/cabinet/app/__init__.py:75]
2019-10-18 12:50:37,478 INFO: Cabinet startup [in /home/matrizaev/cabinet/app/__init__.py:75]
2019-10-18 13:12:22,770 INFO: Cabinet startup [in /home/matrizaev/cabinet/app/__init__.py:75]
2019-10-18 13:12:28,284 INFO: Cabinet startup [in /home/matrizaev/cabinet/app/__init__.py:75]
2019-10-18 13:13:07,082 INFO: Cabinet startup [in /home/matrizaev/cabinet/app/__init__.py:75]
2019-10-18 13:13:16,824 INFO: Cabinet startup [in /home/matrizaev/cabinet/app/__init__.py:75]
2019-10-18 13:14:22,677 INFO: Cabinet startup [in /home/matrizaev/cabinet/app/__init__.py:75]
2019-10-18 13:22:27,553 INFO: Cabinet startup [in /home/matrizaev/cabinet/app/__init__.py:75]
2019-10-18 13:24:04,335 ERROR: Exception on /api/stores/1 [PUT] [in /home/matrizaev/cabinet/venv/lib/python3.6/site-packages/flask/app.py:1891]
Traceback (most recent call last):
  File "/home/matrizaev/cabinet/venv/lib/python3.6/site-packages/flask/app.py", line 2446, in wsgi_app
    response = self.full_dispatch_request()
  File "/home/matrizaev/cabinet/venv/lib/python3.6/site-packages/flask/app.py", line 1951, in full_dispatch_request
    rv = self.handle_user_exception(e)
  File "/home/matrizaev/cabinet/venv/lib/python3.6/site-packages/flask/app.py", line 1820, in handle_user_exception
    reraise(exc_type, exc_value, tb)
  File "/home/matrizaev/cabinet/venv/lib/python3.6/site-packages/flask/_compat.py", line 39, in reraise
    raise value
  File "/home/matrizaev/cabinet/venv/lib/python3.6/site-packages/flask/app.py", line 1949, in full_dispatch_request
    rv = self.dispatch_request()
  File "/home/matrizaev/cabinet/venv/lib/python3.6/site-packages/flask/app.py", line 1935, in dispatch_request
    return self.view_functions[rule.endpoint](**req.view_args)
  File "/home/matrizaev/cabinet/venv/lib/python3.6/site-packages/flask_httpauth.py", line 105, in decorated
    return f(*args, **kwargs)
  File "/home/matrizaev/cabinet/app/api/stores.py", line 16, in SetStore
    user.section = data.get('section', default = '')
TypeError: get() takes no keyword arguments
2019-10-18 13:25:04,970 INFO: Cabinet startup [in /home/matrizaev/cabinet/app/__init__.py:75]
2019-10-18 13:25:07,995 ERROR: Exception on /api/stores/1 [PUT] [in /home/matrizaev/cabinet/venv/lib/python3.6/site-packages/flask/app.py:1891]
Traceback (most recent call last):
  File "/home/matrizaev/cabinet/venv/lib/python3.6/site-packages/flask/app.py", line 2446, in wsgi_app
    response = self.full_dispatch_request()
  File "/home/matrizaev/cabinet/venv/lib/python3.6/site-packages/flask/app.py", line 1951, in full_dispatch_request
    rv = self.handle_user_exception(e)
  File "/home/matrizaev/cabinet/venv/lib/python3.6/site-packages/flask/app.py", line 1820, in handle_user_exception
    reraise(exc_type, exc_value, tb)
  File "/home/matrizaev/cabinet/venv/lib/python3.6/site-packages/flask/_compat.py", line 39, in reraise
    raise value
  File "/home/matrizaev/cabinet/venv/lib/python3.6/site-packages/flask/app.py", line 1949, in full_dispatch_request
    rv = self.dispatch_request()
  File "/home/matrizaev/cabinet/venv/lib/python3.6/site-packages/flask/app.py", line 1935, in dispatch_request
    return self.view_functions[rule.endpoint](**req.view_args)
  File "/home/matrizaev/cabinet/venv/lib/python3.6/site-packages/flask_httpauth.py", line 105, in decorated
    return f(*args, **kwargs)
  File "/home/matrizaev/cabinet/app/api/stores.py", line 16, in SetStore
    user.section = data['section']
KeyError: 'section'
2019-10-18 13:29:12,620 INFO: Cabinet startup [in /home/matrizaev/cabinet/app/__init__.py:75]
2019-10-23 07:56:20,276 INFO: Cabinet startup [in /home/matrizaev/cabinet/app/__init__.py:75]
