2019-10-16 11:04:09,024 ERROR: Exception on / [GET] [in /home/matrizaev/cabinet/venv/lib/python3.6/site-packages/flask/app.py:1891]
Traceback (most recent call last):
  File "/home/matrizaev/cabinet/venv/lib/python3.6/site-packages/flask/app.py", line 2446, in wsgi_app
    response = self.full_dispatch_request()
  File "/home/matrizaev/cabinet/venv/lib/python3.6/site-packages/flask/app.py", line 1951, in full_dispatch_request
    rv = self.handle_user_exception(e)
  File "/home/matrizaev/cabinet/venv/lib/python3.6/site-packages/flask/app.py", line 1820, in handle_user_exception
    reraise(exc_type, exc_value, tb)
  File "/home/matrizaev/cabinet/venv/lib/python3.6/site-packages/flask/_compat.py", line 39, in reraise
    raise value
  File "/home/matrizaev/cabinet/venv/lib/python3.6/site-packages/flask/app.py", line 1949, in full_dispatch_request
    rv = self.dispatch_request()
  File "/home/matrizaev/cabinet/venv/lib/python3.6/site-packages/flask/app.py", line 1935, in dispatch_request
    return self.view_functions[rule.endpoint](**req.view_args)
  File "/home/matrizaev/cabinet/venv/lib/python3.6/site-packages/flask_login/utils.py", line 259, in decorated_view
    elif not current_user.is_authenticated:
  File "/home/matrizaev/cabinet/venv/lib/python3.6/site-packages/werkzeug/local.py", line 348, in __getattr__
    return getattr(self._get_current_object(), name)
  File "/home/matrizaev/cabinet/venv/lib/python3.6/site-packages/werkzeug/local.py", line 307, in _get_current_object
    return self.__local()
  File "/home/matrizaev/cabinet/venv/lib/python3.6/site-packages/flask_login/utils.py", line 26, in <lambda>
    current_user = LocalProxy(lambda: _get_user())
  File "/home/matrizaev/cabinet/venv/lib/python3.6/site-packages/flask_login/utils.py", line 335, in _get_user
    current_app.login_manager._load_user()
  File "/home/matrizaev/cabinet/venv/lib/python3.6/site-packages/flask_login/login_manager.py", line 359, in _load_user
    return self.reload_user()
  File "/home/matrizaev/cabinet/venv/lib/python3.6/site-packages/flask_login/login_manager.py", line 321, in reload_user
    user = self.user_callback(user_id)
  File "/home/matrizaev/cabinet/app/models.py", line 15, in load_user
    return User.query.get(int(id))
  File "/home/matrizaev/cabinet/venv/lib/python3.6/site-packages/flask_sqlalchemy/__init__.py", line 517, in __get__
    mapper = orm.class_mapper(type)
  File "/home/matrizaev/cabinet/venv/lib/python3.6/site-packages/sqlalchemy/orm/base.py", line 441, in class_mapper
    mapper = _inspect_mapped_class(class_, configure=configure)
  File "/home/matrizaev/cabinet/venv/lib/python3.6/site-packages/sqlalchemy/orm/base.py", line 420, in _inspect_mapped_class
    mapper._configure_all()
  File "/home/matrizaev/cabinet/venv/lib/python3.6/site-packages/sqlalchemy/orm/mapper.py", line 1337, in _configure_all
    configure_mappers()
  File "/home/matrizaev/cabinet/venv/lib/python3.6/site-packages/sqlalchemy/orm/mapper.py", line 3244, in configure_mappers
    raise e
sqlalchemy.exc.InvalidRequestError: One or more mappers failed to initialize - can't proceed with initialization of other mappers. Triggering mapper: 'mapped class OrderProducts->order_products'. Original exception was: Could not determine join condition between parent/child tables on relationship OrderProducts.product - there are no foreign keys linking these tables.  Ensure that referencing columns are associated with a ForeignKey or ForeignKeyConstraint, or specify a 'primaryjoin' expression.
2019-10-16 11:07:04,882 INFO: Cabinet startup [in /home/matrizaev/cabinet/app/__init__.py:73]
2019-10-16 11:07:18,158 INFO: Cabinet startup [in /home/matrizaev/cabinet/app/__init__.py:73]
2019-10-16 11:07:24,803 INFO: Cabinet startup [in /home/matrizaev/cabinet/app/__init__.py:73]
2019-10-16 11:07:32,932 INFO: Cabinet startup [in /home/matrizaev/cabinet/app/__init__.py:73]
2019-10-16 11:08:53,048 INFO: Cabinet startup [in ./app/__init__.py:73]
2019-10-16 11:09:55,883 ERROR: Exception on /orders/ [GET] [in /home/matrizaev/cabinet/venv/lib/python3.6/site-packages/flask/app.py:1891]
Traceback (most recent call last):
  File "/home/matrizaev/cabinet/venv/lib/python3.6/site-packages/flask/app.py", line 2446, in wsgi_app
    response = self.full_dispatch_request()
  File "/home/matrizaev/cabinet/venv/lib/python3.6/site-packages/flask/app.py", line 1951, in full_dispatch_request
    rv = self.handle_user_exception(e)
  File "/home/matrizaev/cabinet/venv/lib/python3.6/site-packages/flask/app.py", line 1820, in handle_user_exception
    reraise(exc_type, exc_value, tb)
  File "/home/matrizaev/cabinet/venv/lib/python3.6/site-packages/flask/_compat.py", line 39, in reraise
    raise value
  File "/home/matrizaev/cabinet/venv/lib/python3.6/site-packages/flask/app.py", line 1949, in full_dispatch_request
    rv = self.dispatch_request()
  File "/home/matrizaev/cabinet/venv/lib/python3.6/site-packages/flask/app.py", line 1935, in dispatch_request
    return self.view_functions[rule.endpoint](**req.view_args)
  File "/home/matrizaev/cabinet/venv/lib/python3.6/site-packages/flask_login/utils.py", line 261, in decorated_view
    return func(*args, **kwargs)
  File "/home/matrizaev/cabinet/app/main/routes.py", line 75, in ShowOrders
    return render_template('orders.html', menuItem = 1, orders = orders, form = form)
  File "/home/matrizaev/cabinet/venv/lib/python3.6/site-packages/flask/templating.py", line 140, in render_template
    ctx.app,
  File "/home/matrizaev/cabinet/venv/lib/python3.6/site-packages/flask/templating.py", line 120, in _render
    rv = template.render(context)
  File "/home/matrizaev/cabinet/venv/lib/python3.6/site-packages/jinja2/asyncsupport.py", line 76, in render
    return original_render(self, *args, **kwargs)
  File "/home/matrizaev/cabinet/venv/lib/python3.6/site-packages/jinja2/environment.py", line 1008, in render
    return self.environment.handle_exception(exc_info, True)
  File "/home/matrizaev/cabinet/venv/lib/python3.6/site-packages/jinja2/environment.py", line 780, in handle_exception
    reraise(exc_type, exc_value, tb)
  File "/home/matrizaev/cabinet/venv/lib/python3.6/site-packages/jinja2/_compat.py", line 37, in reraise
    raise value.with_traceback(tb)
  File "/home/matrizaev/cabinet/app/templates/orders.html", line 1, in top-level template code
    {% extends "base.html" %}
  File "/home/matrizaev/cabinet/app/templates/base.html", line 81, in top-level template code
    {% block content %}{% endblock %}
  File "/home/matrizaev/cabinet/app/templates/orders.html", line 64, in block "content"
    {% include '_order.html' %}
  File "/home/matrizaev/cabinet/app/templates/_order.html", line 49, in top-level template code
    {{ product.title }}
  File "/home/matrizaev/cabinet/venv/lib/python3.6/site-packages/jinja2/environment.py", line 430, in getattr
    return getattr(obj, attribute)
jinja2.exceptions.UndefinedError: 'app.models.OrderProducts object' has no attribute 'product'
2019-10-16 11:12:43,694 INFO: Cabinet startup [in /home/matrizaev/cabinet/app/__init__.py:73]
2019-10-16 11:13:53,144 INFO: Cabinet startup [in ./app/__init__.py:73]
2019-10-16 11:18:06,877 INFO: Cabinet startup [in /home/matrizaev/cabinet/app/__init__.py:73]
2019-10-16 11:30:44,679 INFO: Cabinet startup [in /home/matrizaev/cabinet/app/__init__.py:73]
2019-10-16 11:47:58,713 INFO: Cabinet startup [in /home/matrizaev/cabinet/app/__init__.py:73]
2019-10-16 11:52:47,853 INFO: Cabinet startup [in /home/matrizaev/cabinet/app/__init__.py:73]
2019-10-16 11:53:29,678 INFO: Cabinet startup [in /home/matrizaev/cabinet/app/__init__.py:73]
2019-10-16 12:20:37,591 INFO: Cabinet startup [in /home/matrizaev/cabinet/app/__init__.py:73]
2019-10-16 12:23:36,397 INFO: Cabinet startup [in /home/matrizaev/cabinet/app/__init__.py:73]
